2025-09-12 00:29:36,216 INFO    MainThread:855946 [wandb_setup.py:_flush():80] Current SDK version is 0.21.1
2025-09-12 00:29:36,217 INFO    MainThread:855946 [wandb_setup.py:_flush():80] Configure stats pid to 855946
2025-09-12 00:29:36,217 INFO    MainThread:855946 [wandb_setup.py:_flush():80] Loading settings from /home/chzhang/.config/wandb/settings
2025-09-12 00:29:36,217 INFO    MainThread:855946 [wandb_setup.py:_flush():80] Loading settings from /data1/chzhang/sci826/src/src_main_dim2/wandb/settings
2025-09-12 00:29:36,217 INFO    MainThread:855946 [wandb_setup.py:_flush():80] Loading settings from environment variables
2025-09-12 00:29:36,218 INFO    MainThread:855946 [wandb_init.py:setup_run_log_directory():703] Logging user logs to /data1/chzhang/sci826/src/src_main_dim2/wandb/run-20250912_002936-754ttwar/logs/debug.log
2025-09-12 00:29:36,218 INFO    MainThread:855946 [wandb_init.py:setup_run_log_directory():704] Logging internal logs to /data1/chzhang/sci826/src/src_main_dim2/wandb/run-20250912_002936-754ttwar/logs/debug-internal.log
2025-09-12 00:29:36,218 INFO    MainThread:855946 [wandb_init.py:init():830] calling init triggers
2025-09-12 00:29:36,218 INFO    MainThread:855946 [wandb_init.py:init():835] wandb.init called with sweep_config: {}
config: {'model': {'partial_pretrain': 'Qwen/Qwen2.5-0.5B-Instruct', 'trust_remote_code': True, 'enable_gradient_checkpointing': True, 'strategy': 'fsdp', 'fsdp_config': {'wrap_policy': {'min_num_params': 0}, 'cpu_offload': True, 'offload_params': True, 'model_dtype': 'bf16'}, 'lora_rank': 8, 'lora_alpha': 16, 'target_modules': ['q_proj', 'k_proj', 'v_proj', 'o_proj', 'gate_proj', 'up_proj', 'down_proj'], 'use_liger': False}, 'data': {'train_files': ['single_turn_data.parquet'], 'val_files': ['multi_turn_data.parquet'], 'prompt_key': 'prompt', 'response_key': 'response', 'messages_key': 'messages', 'max_length': 512, 'truncation': 'right', 'train_batch_size': 1, 'micro_batch_size_per_gpu': 1, 'balance_dp_token': True, 'use_remove_padding': False, 'chat_template': None, 'custom_cls': {'path': '/data1/chzhang/custom_sft_dataset.py', 'name': 'CustomSFTDataset'}}, 'optim': {'lr': 5e-05, 'betas': [0.9, 0.95], 'weight_decay': 0.1, 'clip_grad': 1.0, 'lr_scheduler': 'cosine', 'warmup_steps_ratio': 0.03}, 'trainer': {'total_epochs': 3, 'total_training_steps': None, 'save_freq': 100, 'test_freq': 50, 'device': 'cuda', 'project_name': 'qwen-sft', 'experiment_name': 'qwen2.5-0.5b-custom', 'logger': 'wandb', 'default_local_dir': './checkpoints', 'default_hdfs_dir': None, 'max_ckpt_to_keep': 3, 'resume_mode': 'auto', 'resume_from_path': None, 'checkpoint': {'save_contents': ['model', 'optimizer', 'extra'], 'load_contents': ['model', 'optimizer', 'extra']}}, 'ulysses_sequence_parallel_size': 1, '_wandb': {}}
2025-09-12 00:29:36,218 INFO    MainThread:855946 [wandb_init.py:init():871] starting backend
2025-09-12 00:29:36,441 INFO    MainThread:855946 [wandb_init.py:init():874] sending inform_init request
2025-09-12 00:29:36,459 INFO    MainThread:855946 [wandb_init.py:init():882] backend started and connected
2025-09-12 00:29:36,467 INFO    MainThread:855946 [wandb_init.py:init():953] updated telemetry
2025-09-12 00:29:36,477 INFO    MainThread:855946 [wandb_init.py:init():977] communicating run to backend with 90.0 second timeout
2025-09-12 00:30:07,416 INFO    Thread-1 (wrapped_target):855946 [retry.py:__call__():173] [no run ID] Retry attempt failed:
Traceback (most recent call last):
  File "/data1/chzhang/anaconda3/envs/fyx_verl/lib/python3.13/site-packages/urllib3/connection.py", line 198, in _new_conn
    sock = connection.create_connection(
        (self._dns_host, self.port),
    ...<2 lines>...
        socket_options=self.socket_options,
    )
  File "/data1/chzhang/anaconda3/envs/fyx_verl/lib/python3.13/site-packages/urllib3/util/connection.py", line 85, in create_connection
    raise err
  File "/data1/chzhang/anaconda3/envs/fyx_verl/lib/python3.13/site-packages/urllib3/util/connection.py", line 73, in create_connection
    sock.connect(sa)
    ~~~~~~~~~~~~^^^^
TimeoutError: timed out

The above exception was the direct cause of the following exception:

Traceback (most recent call last):
  File "/data1/chzhang/anaconda3/envs/fyx_verl/lib/python3.13/site-packages/urllib3/connectionpool.py", line 787, in urlopen
    response = self._make_request(
        conn,
    ...<10 lines>...
        **response_kw,
    )
  File "/data1/chzhang/anaconda3/envs/fyx_verl/lib/python3.13/site-packages/urllib3/connectionpool.py", line 488, in _make_request
    raise new_e
  File "/data1/chzhang/anaconda3/envs/fyx_verl/lib/python3.13/site-packages/urllib3/connectionpool.py", line 464, in _make_request
    self._validate_conn(conn)
    ~~~~~~~~~~~~~~~~~~~^^^^^^
  File "/data1/chzhang/anaconda3/envs/fyx_verl/lib/python3.13/site-packages/urllib3/connectionpool.py", line 1093, in _validate_conn
    conn.connect()
    ~~~~~~~~~~~~^^
  File "/data1/chzhang/anaconda3/envs/fyx_verl/lib/python3.13/site-packages/urllib3/connection.py", line 753, in connect
    self.sock = sock = self._new_conn()
                       ~~~~~~~~~~~~~~^^
  File "/data1/chzhang/anaconda3/envs/fyx_verl/lib/python3.13/site-packages/urllib3/connection.py", line 207, in _new_conn
    raise ConnectTimeoutError(
    ...<2 lines>...
    ) from e
urllib3.exceptions.ConnectTimeoutError: (<urllib3.connection.HTTPSConnection object at 0x7fc536ea11d0>, 'Connection to api.wandb.ai timed out. (connect timeout=20)')

The above exception was the direct cause of the following exception:

Traceback (most recent call last):
  File "/data1/chzhang/anaconda3/envs/fyx_verl/lib/python3.13/site-packages/requests/adapters.py", line 667, in send
    resp = conn.urlopen(
        method=request.method,
    ...<9 lines>...
        chunked=chunked,
    )
  File "/data1/chzhang/anaconda3/envs/fyx_verl/lib/python3.13/site-packages/urllib3/connectionpool.py", line 841, in urlopen
    retries = retries.increment(
        method, url, error=new_e, _pool=self, _stacktrace=sys.exc_info()[2]
    )
  File "/data1/chzhang/anaconda3/envs/fyx_verl/lib/python3.13/site-packages/urllib3/util/retry.py", line 519, in increment
    raise MaxRetryError(_pool, url, reason) from reason  # type: ignore[arg-type]
    ^^^^^^^^^^^^^^^^^^^^^^^^^^^^^^^^^^^^^^^^^^^^^^^^^^^
urllib3.exceptions.MaxRetryError: HTTPSConnectionPool(host='api.wandb.ai', port=443): Max retries exceeded with url: /graphql (Caused by ConnectTimeoutError(<urllib3.connection.HTTPSConnection object at 0x7fc536ea11d0>, 'Connection to api.wandb.ai timed out. (connect timeout=20)'))

During handling of the above exception, another exception occurred:

Traceback (most recent call last):
  File "/data1/chzhang/anaconda3/envs/fyx_verl/lib/python3.13/site-packages/wandb/sdk/lib/retry.py", line 134, in __call__
    result = self._call_fn(*args, **kwargs)
  File "/data1/chzhang/anaconda3/envs/fyx_verl/lib/python3.13/site-packages/wandb/sdk/internal/internal_api.py", line 398, in execute
    return self.client.execute(*args, **kwargs)  # type: ignore
           ~~~~~~~~~~~~~~~~~~~^^^^^^^^^^^^^^^^^
  File "/data1/chzhang/anaconda3/envs/fyx_verl/lib/python3.13/site-packages/wandb/vendor/gql-0.2.0/wandb_gql/client.py", line 52, in execute
    result = self._get_result(document, *args, **kwargs)
  File "/data1/chzhang/anaconda3/envs/fyx_verl/lib/python3.13/site-packages/wandb/vendor/gql-0.2.0/wandb_gql/client.py", line 60, in _get_result
    return self.transport.execute(document, *args, **kwargs)
           ~~~~~~~~~~~~~~~~~~~~~~^^^^^^^^^^^^^^^^^^^^^^^^^^^
  File "/data1/chzhang/anaconda3/envs/fyx_verl/lib/python3.13/site-packages/wandb/sdk/lib/gql_request.py", line 58, in execute
    request = self.session.post(self.url, **post_args)
  File "/data1/chzhang/anaconda3/envs/fyx_verl/lib/python3.13/site-packages/requests/sessions.py", line 637, in post
    return self.request("POST", url, data=data, json=json, **kwargs)
           ~~~~~~~~~~~~^^^^^^^^^^^^^^^^^^^^^^^^^^^^^^^^^^^^^^^^^^^^^
  File "/data1/chzhang/anaconda3/envs/fyx_verl/lib/python3.13/site-packages/requests/sessions.py", line 589, in request
    resp = self.send(prep, **send_kwargs)
  File "/data1/chzhang/anaconda3/envs/fyx_verl/lib/python3.13/site-packages/requests/sessions.py", line 703, in send
    r = adapter.send(request, **kwargs)
  File "/data1/chzhang/anaconda3/envs/fyx_verl/lib/python3.13/site-packages/requests/adapters.py", line 688, in send
    raise ConnectTimeout(e, request=request)
requests.exceptions.ConnectTimeout: HTTPSConnectionPool(host='api.wandb.ai', port=443): Max retries exceeded with url: /graphql (Caused by ConnectTimeoutError(<urllib3.connection.HTTPSConnection object at 0x7fc536ea11d0>, 'Connection to api.wandb.ai timed out. (connect timeout=20)'))
